<?xml version="1.0" encoding="utf-8"?>
<!-- This URDF was automatically created by SolidWorks to URDF Exporter! Originally created by Stephen Brawner (brawner@gmail.com) 
     Commit Version: 1.6.0-4-g7f85cfe  Build Version: 1.6.7995.38578
     For more information, please see http://wiki.ros.org/sw_urdf_exporter -->
<robot
  name="Robot_Arm_URDF">
  <link
    name="base_link">
    <inertial>
      <origin
        xyz="0.00167981419229938 6.47211935710871E-05 0.0286117256120266"
        rpy="0 0 0" />
      <mass
        value="0.208993334963106" />
      <inertia
        ixx="0.000146071554614992"
        ixy="-7.53974206087624E-13"
        ixz="-7.61368540111299E-07"
        iyy="0.00016127704980574"
        iyz="2.54283923386769E-08"
        izz="0.000251457093191278" />
    </inertial>
    <visual>
      <origin
        xyz="0 0 0"
        rpy="0 0 0" />
      <geometry>
        <mesh
          filename="package://Robot_Arm_URDF/meshes/base_link.STL" />
      </geometry>
      <material
        name="">
        <color
          rgba="0.792156862745098 0.819607843137255 0.933333333333333 1" />
      </material>
    </visual>
    <collision>
      <origin
        xyz="0 0 0"
        rpy="0 0 0" />
      <geometry>
        <mesh
          filename="package://Robot_Arm_URDF/meshes/base_link.STL" />
      </geometry>
    </collision>
  </link>
  <link
    name="Link_1">
    <inertial>
      <origin
        xyz="9.89955968762335E-12 -0.00149066382813459 0.023813834252143"
        rpy="0 0 0" />
      <mass
        value="0.0459065811899164" />
      <inertia
        ixx="1.80051627611035E-05"
        ixy="-1.11989261123787E-14"
        ixz="5.62689030622863E-14"
        iyy="2.49369158889534E-05"
        iyz="3.30169256590289E-08"
        izz="1.57950935796408E-05" />
    </inertial>
    <visual>
      <origin
        xyz="0 0 0"
        rpy="0 0 0" />
      <geometry>
        <mesh
          filename="package://Robot_Arm_URDF/meshes/Link_1.STL" />
      </geometry>
      <material
        name="">
        <color
          rgba="0.792156862745098 0.819607843137255 0.933333333333333 1" />
      </material>
    </visual>
    <collision>
      <origin
        xyz="0 0 0"
        rpy="0 0 0" />
      <geometry>
        <mesh
          filename="package://Robot_Arm_URDF/meshes/Link_1.STL" />
      </geometry>
    </collision>
  </link>
  <joint
    name="Joint_0"
    type="revolute">
    <origin
      xyz="-0.001 0 0.0686"
      rpy="0 0 0" />
    <parent
      link="base_link" />
    <child
      link="Link_1" />
    <axis
      xyz="0 0 1" />
    <limit
      lower="-1.57"
      upper="1.57"
      effort="0"
      velocity="0" />
  </joint>
  <link
    name="Link_2">
    <inertial>
      <origin
        xyz="2.84986195449657E-10 0.0756453012159297 0.000594162847007313"
        rpy="0 0 0" />
      <mass
        value="0.127836737110903" />
      <inertia
        ixx="4.58773819783129E-05"
        ixy="-6.75194446043959E-14"
        ixz="-1.14304771619058E-12"
        iyy="2.09726161475232E-05"
        iyz="6.01488176891403E-07"
        izz="4.17836702398218E-05" />
    </inertial>
    <visual>
      <origin
        xyz="0 0 0"
        rpy="0 0 0" />
      <geometry>
        <mesh
          filename="package://Robot_Arm_URDF/meshes/Link_2.STL" />
      </geometry>
      <material
        name="">
        <color
          rgba="0.792156862745098 0.819607843137255 0.933333333333333 1" />
      </material>
    </visual>
    <collision>
      <origin
        xyz="0 0 0"
        rpy="0 0 0" />
      <geometry>
        <mesh
          filename="package://Robot_Arm_URDF/meshes/Link_2.STL" />
      </geometry>
    </collision>
  </link>
  <joint
    name="Joint_1"
    type="revolute">
    <origin
      xyz="0 0 0.0305"
      rpy="1.5708 0 0" />
    <parent
      link="Link_1" />
    <child
      link="Link_2" />
    <axis
      xyz="0 0 1" />
    <limit
      lower="0"
      upper="3.1416"
      effort="0"
      velocity="0" />
  </joint>
  <link
    name="LinK_3">
    <inertial>
      <origin
        xyz="3.28474803997295E-10 0.0597292296297967 0.000316042486816973"
        rpy="0 0 0" />
      <mass
        value="0.125886467693022" />
      <inertia
        ixx="4.01958909359151E-05"
        ixy="-1.0277777371492E-13"
        ixz="-1.03433492911693E-12"
        iyy="2.95892908035324E-05"
        iyz="-2.85211521056863E-07"
        izz="2.7775199110612E-05" />
    </inertial>
    <visual>
      <origin
        xyz="0 0 0"
        rpy="0 0 0" />
      <geometry>
        <mesh
          filename="package://Robot_Arm_URDF/meshes/LinK_3.STL" />
      </geometry>
      <material
        name="">
        <color
          rgba="0.792156862745098 0.819607843137255 0.933333333333333 1" />
      </material>
    </visual>
    <collision>
      <origin
        xyz="0 0 0"
        rpy="0 0 0" />
      <geometry>
        <mesh
          filename="package://Robot_Arm_URDF/meshes/LinK_3.STL" />
      </geometry>
    </collision>
  </link>
  <joint
    name="Joint_2"
    type="revolute">
    <origin
      xyz="0 0.126 0"
      rpy="0 0 0" />
    <parent
      link="Link_2" />
    <child
      link="LinK_3" />
    <axis
      xyz="0 0 1" />
    <limit
      lower="0"
      upper="3.1416"
      effort="0"
      velocity="0" />
  </joint>
  <link
    name="Link_4">
    <inertial>
      <origin
        xyz="0.000262042609690324 0.0399996944961469 -0.000302854759390298"
        rpy="0 0 0" />
      <mass
        value="0.0911239025710441" />
      <inertia
        ixx="3.36589391224374E-05"
        ixy="9.90529975707665E-08"
        ixz="4.85285409404086E-14"
        iyy="3.18623083979145E-05"
        iyz="-2.44528462815815E-07"
        izz="2.43949987617596E-05" />
    </inertial>
    <visual>
      <origin
        xyz="0 0 0"
        rpy="0 0 0" />
      <geometry>
        <mesh
          filename="package://Robot_Arm_URDF/meshes/Link_4.STL" />
      </geometry>
      <material
        name="">
        <color
          rgba="0.792156862745098 0.819607843137255 0.933333333333333 1" />
      </material>
    </visual>
    <collision>
      <origin
        xyz="0 0 0"
        rpy="0 0 0" />
      <geometry>
        <mesh
          filename="package://Robot_Arm_URDF/meshes/Link_4.STL" />
      </geometry>
    </collision>
  </link>
  <joint
    name="Joint_3"
    type="revolute">
    <origin
      xyz="0 0.101 0"
      rpy="0 0 0" />
    <parent
      link="LinK_3" />
    <child
      link="Link_4" />
    <axis
      xyz="0 0 1" />
    <limit
      lower="0"
      upper="3.1416"
      effort="0"
      velocity="0" />
  </joint>
  <link
    name="Link_5">
    <inertial>
      <origin
        xyz="2.03396327558281E-16 3.59998489352087E-15 0.010110034999088"
        rpy="0 0 0" />
      <mass
        value="0.0158680457964435" />
      <inertia
        ixx="2.57485098820088E-06"
        ixy="-5.07419555577374E-16"
        ixz="-1.42357879511555E-22"
        iyy="2.60890328905504E-06"
        iyz="-1.32948562259951E-22"
        izz="4.68375833103543E-06" />
    </inertial>
    <visual>
      <origin
        xyz="0 0 0"
        rpy="0 0 0" />
      <geometry>
        <mesh
          filename="package://Robot_Arm_URDF/meshes/Link_5.STL" />
      </geometry>
      <material
        name="">
        <color
          rgba="0.792156862745098 0.819607843137255 0.933333333333333 1" />
      </material>
    </visual>
    <collision>
      <origin
        xyz="0 0 0"
        rpy="0 0 0" />
      <geometry>
        <mesh
          filename="package://Robot_Arm_URDF/meshes/Link_5.STL" />
      </geometry>
    </collision>
  </link>
  <joint
    name="Joint_4"
    type="revolute">
    <origin
      xyz="0 0.061 -0.00135"
      rpy="1.5708 -1.5708 3.1416" />
    <parent
      link="Link_4" />
    <child
      link="Link_5" />
    <axis
      xyz="0 0 1" />
    <limit
      lower="-1.57"
      upper="3.1416"
      effort="0"
      velocity="0" />
  </joint>
</robot>